üîÑ Acessando o sistema...
‚úÖ Acessando o sistema realizado com sucesso.
üñºÔ∏è Screenshot: screenshots\acessando_o_sistema_120924.png
üñºÔ∏è Screenshot: screenshots\url_acessada_120925.png
üîÑ Realizando login...
‚úÖ Realizando login realizado com sucesso.
üñºÔ∏è Screenshot: screenshots\realizando_login_120927.png
üñºÔ∏è Screenshot: screenshots\login_concluido_120933.png
üîÑ Ajustando zoom...
‚úÖ Ajustando zoom realizado com sucesso.
üñºÔ∏è Screenshot: screenshots\ajustando_zoom_120933.png
üîÑ Abrindo menu Cart√£o...
‚úÖ Abrindo menu Cart√£o realizado com sucesso.
üñºÔ∏è Screenshot: screenshots\abrindo_menu_cart√£o_120937.png
üñºÔ∏è Screenshot: screenshots\menu_aberto_120937.png
üîÑ Acessando formul√°rio...
‚úÖ Acessando formul√°rio realizado com sucesso.
üñºÔ∏è Screenshot: screenshots\acessando_formul√°rio_120939.png
üñºÔ∏è Screenshot: screenshots\formulario_aberto_120939.png
üîÑ Preenchendo campos obrigat√≥rios...
üîÑ Preenchendo campos obrigat√≥rios.
üîÑ Selecionando bandeira...
‚ùå Erro ao tentar selecionando bandeira: Message: 
Stacktrace:
	GetHandleVerifier [0x0x9bc333+65459]
	GetHandleVerifier [0x0x9bc374+65524]
	(No symbol) [0x0x7dd973]
	(No symbol) [0x0x8276e7]
	(No symbol) [0x0x827a8b]
	(No symbol) [0x0x86dea2]
	(No symbol) [0x0x849e44]
	(No symbol) [0x0x86b606]
	(No symbol) [0x0x849bf6]
	(No symbol) [0x0x81b38e]
	(No symbol) [0x0x81c274]
	GetHandleVerifier [0x0xc3eda3+2697763]
	GetHandleVerifier [0x0xc39ec7+2677575]
	GetHandleVerifier [0x0x9e4194+228884]
	GetHandleVerifier [0x0x9d49f8+165496]
	GetHandleVerifier [0x0x9db18d+192013]
	GetHandleVerifier [0x0x9c47d8+99416]
	GetHandleVerifier [0x0x9c4972+99826]
	GetHandleVerifier [0x0x9aebea+10346]
	BaseThreadInitThunk [0x0x755bfcc9+25]
	RtlGetAppContainerNamedObjectPath [0x0x773a82ae+286]
	RtlGetAppContainerNamedObjectPath [0x0x773a827e+238]

üñºÔ∏è Screenshot: screenshots\erro_selecionando_bandeira_120950.png
üìÑ Relat√≥rio salvo como: relatorio_cartoes_cenario_3_20250926_120950.docx
‚úÖ Preenchendo campos obrigat√≥rios realizado com sucesso.
Traceback (most recent call last):
  File "C:\Users\Gold System\AppData\Roaming\Python\Python313\site-packages\urllib3\connection.py", line 198, in _new_conn
    sock = connection.create_connection(
        (self._dns_host, self.port),
    ...<2 lines>...
        socket_options=self.socket_options,
    )
  File "C:\Users\Gold System\AppData\Roaming\Python\Python313\site-packages\urllib3\util\connection.py", line 85, in create_connection
    raise err
  File "C:\Users\Gold System\AppData\Roaming\Python\Python313\site-packages\urllib3\util\connection.py", line 73, in create_connection
    sock.connect(sa)
    ~~~~~~~~~~~~^^^^
ConnectionRefusedError: [WinError 10061] Nenhuma conex√£o p√¥de ser feita porque a m√°quina de destino as recusou ativamente

The above exception was the direct cause of the following exception:

Traceback (most recent call last):
  File "C:\Users\Gold System\AppData\Roaming\Python\Python313\site-packages\urllib3\connectionpool.py", line 787, in urlopen
    response = self._make_request(
        conn,
    ...<10 lines>...
        **response_kw,
    )
  File "C:\Users\Gold System\AppData\Roaming\Python\Python313\site-packages\urllib3\connectionpool.py", line 493, in _make_request
    conn.request(
    ~~~~~~~~~~~~^
        method,
        ^^^^^^^
    ...<6 lines>...
        enforce_content_length=enforce_content_length,
        ^^^^^^^^^^^^^^^^^^^^^^^^^^^^^^^^^^^^^^^^^^^^^^
    )
    ^
  File "C:\Users\Gold System\AppData\Roaming\Python\Python313\site-packages\urllib3\connection.py", line 494, in request
    self.endheaders()
    ~~~~~~~~~~~~~~~^^
  File "C:\Python313\Lib\http\client.py", line 1333, in endheaders
    self._send_output(message_body, encode_chunked=encode_chunked)
    ~~~~~~~~~~~~~~~~~^^^^^^^^^^^^^^^^^^^^^^^^^^^^^^^^^^^^^^^^^^^^^
  File "C:\Python313\Lib\http\client.py", line 1093, in _send_output
    self.send(msg)
    ~~~~~~~~~^^^^^
  File "C:\Python313\Lib\http\client.py", line 1037, in send
    self.connect()
    ~~~~~~~~~~~~^^
  File "C:\Users\Gold System\AppData\Roaming\Python\Python313\site-packages\urllib3\connection.py", line 325, in connect
    self.sock = self._new_conn()
                ~~~~~~~~~~~~~~^^
  File "C:\Users\Gold System\AppData\Roaming\Python\Python313\site-packages\urllib3\connection.py", line 213, in _new_conn
    raise NewConnectionError(
        self, f"Failed to establish a new connection: {e}"
    ) from e
urllib3.exceptions.NewConnectionError: <urllib3.connection.HTTPConnection object at 0x00000122AD706520>: Failed to establish a new connection: [WinError 10061] Nenhuma conex√£o p√¥de ser feita porque a m√°quina de destino as recusou ativamente

The above exception was the direct cause of the following exception:

Traceback (most recent call last):
  File "C:\Users\Gold System\AppData\Local\Temp\_MEI143162\cenariostestespegasus\CadastrosAdicionais\CadastrosCen√°riosCart√µes\cadastrodecart√µes3¬∫cenario.py", line 167, in <module>
    main()
    ~~~~^^
  File "C:\Users\Gold System\AppData\Local\Temp\_MEI143162\cenariostestespegasus\CadastrosAdicionais\CadastrosCen√°riosCart√µes\cadastrodecart√µes3¬∫cenario.py", line 145, in main
    if not safe_action(doc, "Preenchendo campos obrigat√≥rios", preencher_obrigatorios, driver, wait)[0]: finalizar_relatorio(); return
           ~~~~~~~~~~~^^^^^^^^^^^^^^^^^^^^^^^^^^^^^^^^^^^^^^^^^^^^^^^^^^^^^^^^^^^^^^^^^^^^^^^^^^^^^^
  File "C:\RPASelenium\RPAsPegasusSelenium\utils\actions.py", line 37, in safe_action
    take_screenshot(driver, doc, name.lower().replace(" ", "_"))
    ~~~~~~~~~~~~~~~^^^^^^^^^^^^^^^^^^^^^^^^^^^^^^^^^^^^^^^^^^^^^
  File "C:\RPASelenium\RPAsPegasusSelenium\utils\actions.py", line 27, in take_screenshot
    driver.save_screenshot(path)
    ~~~~~~~~~~~~~~~~~~~~~~^^^^^^
  File "C:\Users\Gold System\AppData\Roaming\Python\Python313\site-packages\selenium\webdriver\remote\webdriver.py", line 1025, in save_screenshot
    return self.get_screenshot_as_file(filename)
           ~~~~~~~~~~~~~~~~~~~~~~~~~~~^^^^^^^^^^
  File "C:\Users\Gold System\AppData\Roaming\Python\Python313\site-packages\selenium\webdriver\remote\webdriver.py", line 1000, in get_screenshot_as_file
    png = self.get_screenshot_as_png()
  File "C:\Users\Gold System\AppData\Roaming\Python\Python313\site-packages\selenium\webdriver\remote\webdriver.py", line 1034, in get_screenshot_as_png
    return b64decode(self.get_screenshot_as_base64().encode("ascii"))
                     ~~~~~~~~~~~~~~~~~~~~~~~~~~~~~^^
  File "C:\Users\Gold System\AppData\Roaming\Python\Python313\site-packages\selenium\webdriver\remote\webdriver.py", line 1044, in get_screenshot_as_base64
    return self.execute(Command.SCREENSHOT)["value"]
           ~~~~~~~~~~~~^^^^^^^^^^^^^^^^^^^^
  File "C:\Users\Gold System\AppData\Roaming\Python\Python313\site-packages\selenium\webdriver\remote\webdriver.py", line 455, in execute
    response = cast(RemoteConnection, self.command_executor).execute(driver_command, params)
  File "C:\Users\Gold System\AppData\Roaming\Python\Python313\site-packages\selenium\webdriver\remote\remote_connection.py", line 406, in execute
    return self._request(command_info[0], url, body=data)
           ~~~~~~~~~~~~~^^^^^^^^^^^^^^^^^^^^^^^^^^^^^^^^^
  File "C:\Users\Gold System\AppData\Roaming\Python\Python313\site-packages\selenium\webdriver\remote\remote_connection.py", line 430, in _request
    response = self._conn.request(method, url, body=body, headers=headers, timeout=self._client_config.timeout)
  File "C:\Users\Gold System\AppData\Roaming\Python\Python313\site-packages\urllib3\_request_methods.py", line 135, in request
    return self.request_encode_url(
           ~~~~~~~~~~~~~~~~~~~~~~~^
        method,
        ^^^^^^^
    ...<3 lines>...
        **urlopen_kw,
        ^^^^^^^^^^^^^
    )
    ^
  File "C:\Users\Gold System\AppData\Roaming\Python\Python313\site-packages\urllib3\_request_methods.py", line 182, in request_encode_url
    return self.urlopen(method, url, **extra_kw)
           ~~~~~~~~~~~~^^^^^^^^^^^^^^^^^^^^^^^^^
  File "C:\Users\Gold System\AppData\Roaming\Python\Python313\site-packages\urllib3\poolmanager.py", line 459, in urlopen
    response = conn.urlopen(method, u.request_uri, **kw)
  File "C:\Users\Gold System\AppData\Roaming\Python\Python313\site-packages\urllib3\connectionpool.py", line 871, in urlopen
    return self.urlopen(
           ~~~~~~~~~~~~^
        method,
        ^^^^^^^
    ...<13 lines>...
        **response_kw,
        ^^^^^^^^^^^^^^
    )
    ^
  File "C:\Users\Gold System\AppData\Roaming\Python\Python313\site-packages\urllib3\connectionpool.py", line 871, in urlopen
    return self.urlopen(
           ~~~~~~~~~~~~^
        method,
        ^^^^^^^
    ...<13 lines>...
        **response_kw,
        ^^^^^^^^^^^^^^
    )
    ^
  File "C:\Users\Gold System\AppData\Roaming\Python\Python313\site-packages\urllib3\connectionpool.py", line 871, in urlopen
    return self.urlopen(
           ~~~~~~~~~~~~^
        method,
        ^^^^^^^
    ...<13 lines>...
        **response_kw,
        ^^^^^^^^^^^^^^
    )
    ^
  File "C:\Users\Gold System\AppData\Roaming\Python\Python313\site-packages\urllib3\connectionpool.py", line 841, in urlopen
    retries = retries.increment(
        method, url, error=new_e, _pool=self, _stacktrace=sys.exc_info()[2]
    )
  File "C:\Users\Gold System\AppData\Roaming\Python\Python313\site-packages\urllib3\util\retry.py", line 519, in increment
    raise MaxRetryError(_pool, url, reason) from reason  # type: ignore[arg-type]
    ^^^^^^^^^^^^^^^^^^^^^^^^^^^^^^^^^^^^^^^^^^^^^^^^^^^
urllib3.exceptions.MaxRetryError: HTTPConnectionPool(host='localhost', port=53765): Max retries exceeded with url: /session/0582ad6adaf40f36e66ced86885d2534/screenshot (Caused by NewConnectionError('<urllib3.connection.HTTPConnection object at 0x00000122AD706520>: Failed to establish a new connection: [WinError 10061] Nenhuma conex√£o p√¥de ser feita porque a m√°quina de destino as recusou ativamente'))
