Traceback (most recent call last):
  File "C:\Users\Gold System\AppData\Local\Temp\_MEI55242\cenariostestespegasus\CadastrosAdicionais\CadastrosCenáriosFormulárioDigitalAlternativa\cadastrodeformulariodigitalalternativa1ºcenario.py", line 16, in <module>
    from faker import Faker
  File "C:\Users\Gold System\AppData\Local\Temp\_MEI55242\faker\__init__.py", line 1, in <module>
    from faker.factory import Factory
  File "C:\Users\Gold System\AppData\Local\Temp\_MEI55242\faker\factory.py", line 8, in <module>
    from .config import AVAILABLE_LOCALES, DEFAULT_LOCALE, PROVIDERS
  File "C:\Users\Gold System\AppData\Local\Temp\_MEI55242\faker\config.py", line 13, in <module>
    AVAILABLE_LOCALES = find_available_locales(PROVIDERS)
  File "C:\Users\Gold System\AppData\Local\Temp\_MEI55242\faker\utils\loading.py", line 45, in find_available_locales
    provider_module = import_module(provider_path)
  File "C:\Python313\Lib\importlib\__init__.py", line 88, in import_module
    return _bootstrap._gcd_import(name[level:], package, level)
           ~~~~~~~~~~~~~~~~~~~~~~^^^^^^^^^^^^^^^^^^^^^^^^^^^^^^
  File "C:\Users\Gold System\AppData\Local\Temp\_MEI55242\faker\providers\address\__init__.py", line 1, in <module>
    from .. import BaseProvider, ElementsType, date_time
  File "C:\Users\Gold System\AppData\Local\Temp\_MEI55242\faker\providers\date_time\__init__.py", line 13, in <module>
    from dateutil import relativedelta
ImportError: cannot import name 'relativedelta' from 'dateutil' (unknown location)
